Workbook

Sheet ISIAN DATA
B2: INPUT DATA NIKAH | H2: DATA JADI | M2: Berkas Cetak
B3: Nama Desa | C3: TAMBI | D3: Inputlah Data dengan CERMAT & TELITI! | H3: =UPPER(C3) -> TAMBI | I3: =C9-C8 -> 42 | M3: WAJIB Cetak | N3: PILIHAN Cetak | O3: Ket. Pilihan
B4: Status Jabatan Kades | C4: Definitif | K4: =I14 -> 1 | M4: RDS | N4: N1- Putra | O4: =IF(K4=1,"Cetak","Tidak Cetak") -> Cetak
B5: Nama Kepala Desa | C5: J U R I | H5: =C5 -> J U R I | J5: =IF(I7="7","VII",IF(I7="8","VIII",IF(I7="9","IX",IF(I7="10","X",IF(I7="11","XI","XII"))))) -> X | K5: =I42 -> 1 | M5: Kendali | N5: N1- Putri | O5: =IF(K5=1,"Cetak","Tidak Cetak") -> Cetak
B6: Petugas Pengantar | C6: Chalim Muchtarom, S.Pd.I | H6: =C6 -> Chalim Muchtarom, S.Pd.I | K6: ='N5'!J5 -> #NAME? | M6: N2- Permohonan | N6: N5- Izin Pengampu | O6: {=_xlfn.IFS(K6=1,"Calon Suami",K6=2,"Calon Istri",K6=3,"Keduanya",K6=0,"Tidak Cetak")} -> #NAME?
B7: NO. REGISTER SURAT | C7: 19 | H7: ="400.12.3.2/"&C7&J8 -> 400.12.3.2/19/X/2026 | I7: =TEXT(C8,"M") -> 10 | J7: =IF(I7="1","I",IF(I7="2","II",IF(I7="3","III",IF(I7="4","IV",IF(I7="5","V",IF(I7="6","VI",J5)))))) -> X | K7: =IF(H73="AYAH KANDUNG",0,1) -> 0 | M7: N4- Persetujuan | N7: SKW | O7: =IF(K7=1,"Cetak","Tidak Cetak") -> Tidak Cetak
B8: TANGGAL SURAT | C8: 46303 | D8: =IF(I3<1,"Salah Input Tanggal!","Betul!") -> Betul! | H8: =PROPER(C3)&", "&(TEXT(C8,"DD MMMM YYYY")) -> Tambi, 08 Oktober 2026 | J8: ="/"&J7&"/"&RIGHT(H9,4) -> /X/2026 | K8: =I73 -> #NAME? | N8: Super WH | O8: =IF(K8>0,"Cetak","Tidak Cetak") -> #NAME?
B9: TANGGAL PELAKSANAAN | C9: 46345 | D9: =IF(I3<1,"",IF(I3<14,"Perlu Dispensasi Camat!","")) | H9: =UPPER(J9&", "&(TEXT(C9,"DD MMMM YYYY"))) -> KAMIS, 19 NOVEMBER 2026 | I9: =TEXT(C9, "DDDD") -> Kamis | J9: =IF(I9="Minggu","Ahad",I9) -> Kamis | K9: =IF(I3<10,1,0) -> 0 | N9: Dispensasi | O9: =IF(K9=1,"Cetak","Tidak Cetak") -> Tidak Cetak
B10: WAKTU | C10: JAM : 08:30 | D10: KETERBATASAN WAKTU CUTI DARI PEMBERI KERJA | G10: LUAR KANTOR | H10: =PROPER(H9) -> Kamis, 19 November 2026 | I10: =IF(D9="","",UPPER(D10)) | M10: FILE NON CETAK
B11: TEMPAT AKAD NIKAH | C11: Dsn Simadu RT 003 RW 008 Desa Badak Kecamatan Belik Kabupaten Pemalang | E11: LUAR KANTOR | G11: KANTOR | H11: =IF(E11="KANTOR","BALAI NIKAH KUA WATUKUMPUL",UPPER(C11)) -> DSN SIMADU RT 003 RW 008 DESA BADAK KECAMATAN BELIK KABUPATEN PEMALANG | M11: RDS WhatsApp | N11: Kamus Data
B13: CALON PENGANTIN LAKI-LAKI | D13: Orang tua ---> | E13: BERSAMA | G13: =E13 -> BERSAMA | H13: =IF(G14=2,G13,"-") -> BERSAMA
B14: 1. Nama Lengkap | C14: AOFA ARDIAN FADILLAH AZIZ | E14: LOKAL | G14: =G32+G23 -> 2 | H14: =UPPER(C14) -> AOFA ARDIAN FADILLAH AZIZ | I14: =IF(E14="LOKAL",1,2) -> 1
B15: 2. NIK |Pendidikan | C15: 3327041308020004 | D15: SLTA | E15: <<< Ada Pilihan | H15: =C15 -> 3327041308020004
B16: 3. Tempat |Tanggal Lahir | C16: PEMALANG | D16: 37481 | E16: <<< Ada Pilihan | H16: =I16 -> PEMALANG, 13 AGUSTUS 2002 | I16: =UPPER(C16&", "&TEXT(D16,"D MMMM YYYY")) -> PEMALANG, 13 AGUSTUS 2002 | J16: =NOW()-D16 -> 8822.3839
B17: 4. Pekerjaan | C17: WIRASWASTA | D17: …. | E17: <<< Pilihan & Isian Manual | H17: =UPPER(I17) -> WIRASWASTA | I17: =IF(C17="Lainnya",D17,C17) -> WIRASWASTA | J17: =TEXT(J16,"YY") -> 24
B18: 5. Kewarganegaraan | C18: INDONESIA | D18: …. | E18: <<< Pilihan & Isian Manual | H18: =UPPER(IF(C18="WNA",D18,C18)) -> INDONESIA
B19: 6. Status |Beristri Ke … | C19: JEJAKA (BELUM KAWIN) | E19: <<< Ada Pilihan : 2 | H19: =C19 -> JEJAKA (BELUM KAWIN) | I19: =IF(H19="BERISTRI",UPPER(D19),"") | J19: {=_xlfn.IFS(H19="JEJAKA (BELUM KAWIN)","Jejaka",H19="BERISTRI","Beristri",TRUE,"Duda")&" - "&D15} -> Jejaka - SLTA
B20: 7. Alamat | C20: DK. Tambi RT 002 RW 001 Tambi | E20: <<< Isian Manual | H20: =UPPER(C20) -> DK. TAMBI RT 002 RW 001 TAMBI
C21: Kec. Watukumpul Kab. Pemalang | E21: <<< Isian Manual | H21: =UPPER(C21) -> KEC. WATUKUMPUL KAB. PEMALANG
B23: 1. Nama AYAH |Bin | C23: TOHIRIN | D23: MUHAYAT | E23: Hidup | G23: =IF(E23="Hidup",1,0) -> 1 | H23: =IF(E23="Sepi Ayah","-.-.",IF(E23="MENINGGAL",(C23&" (ALM)"),C23)) -> TOHIRIN | I23: =PROPER(C23) -> Tohirin | J23: =IF(E23="Sepi Ayah",I32,I23) -> Tohirin
B24: 2. NIK | C24: 3327040107730222 | H24: =IF(E23="Hidup",C24,"-") -> 3327040107730222
B25: 3. Tempat |Tanggal Lahir | C25: PEMALANG | D25: 26846 | H25: =IF(E23="Hidup",I25,"-") -> PEMALANG, 1 JULI 1973 | I25: =UPPER(C25&", "&TEXT(D25,"D MMMM YYYY")) -> PEMALANG, 1 JULI 1973
B26: 4. Kewarganegaraan | C26: INDONESIA | D26: …….. | H26: =IF(E23="Hidup",C26,"-") -> INDONESIA
B27: 5. Agama | C27: ISLAM | D27: …….. | H27: =IF(E23="Hidup",C27,"-") -> ISLAM
B28: 6. Pekerjaan | C28: WIRASWASTA | H28: =IF(E23="Hidup",I28,"-") -> WIRASWASTA | I28: =IF(C28="Lainnya",D28,C28) -> WIRASWASTA
B29: 7. Alamat | C29: DK. Tambi RT 002 RW 001 Tambi | E29: Alamat Calon | H29: =IF(E23="Meninggal","-",I29) -> DK. TAMBI RT 002 RW 001 TAMBI | I29: =IF(E23="Sepi Ayah","-",IF(E23="Hidup",J29,"Tidak Diketahui Keberadaannya")) -> DK. TAMBI RT 002 RW 001 TAMBI | J29: =UPPER(IF(E29="Alamat Sendiri",C29,H20)) -> DK. TAMBI RT 002 RW 001 TAMBI
C30: Kec. Watukumpul Kab. Pemalang | H30: =IF(OR(E23="Meninggal",E23="Miruda"),"-",I30) -> KEC. WATUKUMPUL KAB. PEMALANG | I30: =IF(E23="Sepi Ayah","-",IF(E23="Hidup",J30,"Tidak Diketahui Keberadaannya")) -> KEC. WATUKUMPUL KAB. PEMALANG | J30: =UPPER(IF(E30="Alamat Sendiri",C30,H21)) -> KEC. WATUKUMPUL KAB. PEMALANG
B32: 1. Nama IBU |Binti | C32: KARIPAH | D32: SUMARTO | E32: Hidup | G32: =IF(E32="Hidup",1,0) -> 1 | H32: =UPPER(IF(E32="MENINGGAL",(C32&" (ALM)"),C32)) -> KARIPAH | I32: =PROPER(C32)&" (IBU)" -> Karipah (IBU)
B33: 2. NIK | C33: 3327044107740064 | H33: =IF(E32="Hidup",C33,"-") -> 3327044107740064
B34: 3. Tempat |Tanggal Lahir | C34: PEMALANG | D34: 27211 | H34: =IF(E32="Hidup",I34,"-") -> PEMALANG, 1 JULI 1974 | I34: =UPPER(C34&", "&TEXT(D34,"D MMMM YYYY")) -> PEMALANG, 1 JULI 1974
B35: 4. Kewarganegaraan | C35: INDONESIA | D35: …. | H35: =IF(E32="Hidup",I35,"-") -> INDONESIA | I35: =UPPER(IF(C35="WNA",D35,C35)) -> INDONESIA
B36: 5. Agama | C36: ISLAM | D36: …. | H36: =IF(E32="Hidup",I36,"-") -> ISLAM | I36: =C36 -> ISLAM
B37: 6. Pekerjaan | C37: MENGURUS RUMAH TANGGA | H37: =IF(E32="Hidup",I37,"-") -> MENGURUS RUMAH TANGGA | I37: =IF(C37="Lainnya",D37,C37) -> MENGURUS RUMAH TANGGA
B38: 7. Alamat | C38: DK. Tambi RT 002 RW 001 Tambi | E38: Alamat Sendiri | H38: =IF(E32="Hidup",I38,"-") -> DK. TAMBI RT 002 RW 001 TAMBI | I38: =UPPER(IF(E38="Alamat Calon",C20,IF(E38="Alamat Suami",H29,C38))) -> DK. TAMBI RT 002 RW 001 TAMBI
C39: Kec. Watukumpul Kab. Pemalang | H39: =IF(E32="Hidup",I39,"-") -> KEC. WATUKUMPUL KAB. PEMALANG | I39: =UPPER(IF(E38="Alamat Calon",C21,IF(E38="Alamat Suami",H30,C39))) -> KEC. WATUKUMPUL KAB. PEMALANG
B41: CALON PENGANTIN PEREMPUAN | D41: Orang tua ---> | E41: BERSAMA | G41: =E41 -> BERSAMA | H41: =IF(G42=2,G41,"-") -> BERSAMA
B42: 1. Nama Lengkap | C42: FIKA INTAN ELMASARI | E42: LOKAL | G42: =G60+G51 -> 2 | H42: =UPPER(C42) -> FIKA INTAN ELMASARI | I42: =IF(E42="LOKAL",1,2) -> 1
B43: 2. NIK |Pendidikan | C43: 3327034810050002 | D43: SLTA | E43: <<< Ada Pilihan | H43: =C43 -> 3327034810050002
B44: 3. Tempat |Tanggal Lahir | C44: PEMALANG | D44: 38633 | E44: <<< Ada Pilihan | H44: =I44 -> PEMALANG, 8 OKTOBER 2005 | I44: =UPPER(C44&", "&TEXT(D44,"D MMMM YYYY")) -> PEMALANG, 8 OKTOBER 2005 | J44: =NOW()-D44 -> 7670.3839
B45: 4. Pekerjaan | C45: Lainnya | D45: Pelajar Mahasiswa | E45: <<< Pilihan & Isian Manual | H45: =UPPER(I45) -> PELAJAR MAHASISWA | I45: =IF(C45="Lainnya",D45,C45) -> Pelajar Mahasiswa | J45: =TEXT(J44,"YY") -> 20
...

Sheet RDS
B1: Cetak Konsep RDS
C2: REKAM DATA SEMENTARA
C3: PENDAFTARAN CALON PASANGAN PENGANTIN
C5: A. | D5: PELAKSANAAN
E6: Hari, Tanggal | F6: ='ISIAN DATA'!H9 -> KAMIS, 19 NOVEMBER 2026 | H6: =PROPER('ISIAN DATA'!C10)&" WIB" -> Jam : 08:30 WIB
E7: Lokasi Akad Nikah | F7: ='ISIAN DATA'!H11 -> DSN SIMADU RT 003 RW 008 DESA BADAK KECAMATAN BELIK KABUPATEN PEMALANG
E8: Email Catin | F8: _____________________________ @gmail.com -
C10: B. | D10: CALON SUAMI
D11: 1. | E11: Nama Lengkap | F11: ='ISIAN DATA'!H14 -> AOFA ARDIAN FADILLAH AZIZ
E12: Temp., tgl lahir | F12: =PROPER('ISIAN DATA'!H16) -> Pemalang, 13 Agustus 2002 | G12: NIK | H12: =L14 -> 332704 - 130802 - 0004 | L12: ='ISIAN DATA'!H15 -> 3327041308020004 | M12: =LEFT(L12,6) -> 332704
E13: Nomor HP | F13: +62 8 | G13: Pendidikan | H13: ='ISIAN DATA'!D15 -> SLTA | L13: =LEFT(L12,12) -> 332704130802 | M13: =RIGHT(L13,6) -> 130802
E14: Pekerjaan | F14: =PROPER('ISIAN DATA'!H17) -> Wiraswasta | G14: Anak ke | L14: =M12&" - "&M13&" - "&M14 -> 332704 - 130802 - 0004 | M14: =RIGHT(L12,4) -> 0004
E15: Status | F15: ='ISIAN DATA'!H19 -> JEJAKA (BELUM KAWIN)
E16: Alamat | F16: =PROPER('ISIAN DATA'!H29&" "&'ISIAN DATA'!H21) -> Dk. Tambi Rt 002 Rw 001 Tambi Kec. Watukumpul Kab. Pemalang
E17: No. & tgl putusan | G17: Tanggal
D19: 2. | E19: Ayah Kandung | F19: ='ISIAN DATA'!H23 -> TOHIRIN | G19: NIK | H19: =L21 -> 332704 - 010773 - 0222 | L19: ='ISIAN DATA'!H24 -> 3327040107730222 | M19: =LEFT(L19,6) -> 332704
E20: Temp., tgl lahir | F20: =PROPER('ISIAN DATA'!H25) -> Pemalang, 1 Juli 1973 | G20: Pekerjaan | H20: =PROPER('ISIAN DATA'!H28) -> Wiraswasta | L20: =LEFT(L19,12) -> 332704010773 | M20: =RIGHT(L20,6) -> 010773
E21: Alamat | F21: =PROPER(('ISIAN DATA'!H29)&" "&'ISIAN DATA'!H30) -> Dk. Tambi Rt 002 Rw 001 Tambi Kec. Watukumpul Kab. Pemalang | L21: =M19&" - "&M20&" - "&M21 -> 332704 - 010773 - 0222 | M21: =RIGHT(L19,4) -> 0222
D23: 3. | E23: Ibu Kandung | F23: =('ISIAN DATA'!H32) -> KARIPAH | G23: NIK | H23: =L25 -> 332704 - 410774 - 0064 | L23: ='ISIAN DATA'!H33 -> 3327044107740064 | M23: =LEFT(L23,6) -> 332704
E24: Temp., tgl lahir | F24: =PROPER('ISIAN DATA'!H34) -> Pemalang, 1 Juli 1974 | G24: Pekerjaan | H24: =PROPER('ISIAN DATA'!H37) -> Mengurus Rumah Tangga | L24: =LEFT(L23,12) -> 332704410774 | M24: =RIGHT(L24,6) -> 410774
E25: Alamat | F25: =PROPER(('ISIAN DATA'!H38&" "&'ISIAN DATA'!H39)) -> Dk. Tambi Rt 002 Rw 001 Tambi Kec. Watukumpul Kab. Pemalang | L25: =M23&" - "&M24&" - "&M25 -> 332704 - 410774 - 0064 | M25: =RIGHT(L23,4) -> 0064
H26: ="Status Ortu : "&'ISIAN DATA'!H13 -> Status Ortu : BERSAMA
C27: C. | D27: CALON ISTRI
D28: 1. | E28: Nama Lengkap | F28: ='ISIAN DATA'!H42 -> FIKA INTAN ELMASARI
E29: Temp., tgl lahir | F29: =PROPER('ISIAN DATA'!H44) -> Pemalang, 8 Oktober 2005 | G29: NIK | H29: =L31 -> 332703 - 481005 - 0002 | L29: ='ISIAN DATA'!H43 -> 3327034810050002 | M29: =LEFT(L29,6) -> 332703
E30: Nomor HP | F30: +62 8 | G30: Pendidikan | H30: ='ISIAN DATA'!D43 -> SLTA | L30: =LEFT(L29,12) -> 332703481005 | M30: =RIGHT(L30,6) -> 481005
E31: Pekerjaan | F31: =PROPER('ISIAN DATA'!H45) -> Pelajar Mahasiswa | G31: Anak ke | L31: =M29&" - "&M30&" - "&M31 -> 332703 - 481005 - 0002 | M31: =RIGHT(L29,4) -> 0002
E32: Status | F32: ='ISIAN DATA'!H47 -> PERAWAN (BELUM KAWIN)
E33: Alamat | F33: =PROPER(('ISIAN DATA'!H48)&" "&'ISIAN DATA'!H49) -> Dsn Simadu Rt 003 Rw 008 Desa Badak Kecamatan Belik Kabupaten Pemalang
E34: No. & tgl putusan | G34: Tanggal
D36: 2. | E36: Ayah Kandung | F36: ='ISIAN DATA'!H51 -> SAMIUN | G36: NIK | H36: =L38 -> 332703 - 110381 - 0011 | L36: ='ISIAN DATA'!H52 -> 3327031103810011 | M36: =LEFT(L36,6) -> 332703
E37: Temp., tgl lahir | F37: =PROPER('ISIAN DATA'!H53) -> Pemalang, 11 Maret 1981 | G37: Pekerjaan | H37: =PROPER('ISIAN DATA'!H56) -> Petani | L37: =LEFT(L36,12) -> 332703110381 | M37: =RIGHT(L37,6) -> 110381
E38: Tempat tinggal | F38: =PROPER(('ISIAN DATA'!H57&" "&'ISIAN DATA'!H58)) -> Dsn Simadu Rt 003 Rw 008 Desa Badak Kecamatan Belik Kabupaten Pemalang | L38: =M36&" - "&M37&" - "&M38 -> 332703 - 110381 - 0011 | M38: =RIGHT(L36,4) -> 0011
D40: 3. | E40: Ibu kandung | F40: ='ISIAN DATA'!H60 -> SRINANI | G40: NIK | H40: =L42 -> 332703 - 410187 - 0012 | L40: ='ISIAN DATA'!H61 -> 3327034101870012 | M40: =LEFT(L40,6) -> 332703
E41: Temp., tgl lahir | F41: =PROPER('ISIAN DATA'!H62) -> Pemalang, 1 Januari 1987 | G41: Pekerjaan | H41: =PROPER('ISIAN DATA'!H65) -> Mengurus Rumah Tangga | L41: =LEFT(L40,12) -> 332703410187 | M41: =RIGHT(L41,6) -> 410187
E42: Tempat tinggal | F42: =PROPER('ISIAN DATA'!H66&" "&'ISIAN DATA'!H67) -> Dsn Simadu Rt 003 Rw 008 Desa Badak Kecamatan Belik Kabupaten Pemalang | L42: =M40&" - "&M41&" - "&M42 -> 332703 - 410187 - 0012 | M42: =RIGHT(L40,4) -> 0012
H43: ="Status Ortu : "&'ISIAN DATA'!H41 -> Status Ortu : BERSAMA
C44: D. | D44: PERWALIAN NASAB
D45: Nama Wali | F45: ='ISIAN DATA'!H75 -> SAMIUN | G45: Bin | H45: ='ISIAN DATA'!H76 -> WASNURI | L45: ='ISIAN DATA'!H77 -> 3327031103810011 | M45: =LEFT(L45,6) -> 332703
D46: Temp., tgl lahir | F46: =PROPER('ISIAN DATA'!H78) -> Pemalang, 11 Maret 1981 | G46: NIK | H46: =L47 -> 332703 - 110381 - 0011 | L46: =LEFT(L45,12) -> 332703110381 | M46: =RIGHT(L46,6) -> 110381
...

Sheet N2
H2: Penyesuaian Lampiran VI
H3: Keputusan Dirjen Bimas Islam Nomor 473 Tahun 2020
B5: Perihal | D5: : Permohonan Kehendak Nikah | H5: ='ISIAN DATA'!H8 -> Tambi, 08 Oktober 2026
B7: Kepada Yth.
B8: Kepala KUA Watukumpul
B9: di WATUKUMPUL
B11: Assalamu'alaikum Warahmatullahi Wabarakatuh
B12: Dengan hormat, kami mengajukan permohonan kehendak pernikahan untuk atas nama:
B14: Calon suami | E14: : | F14: ='ISIAN DATA'!H14 &" Bin "&'ISIAN DATA'!H23 -> AOFA ARDIAN FADILLAH AZIZ Bin TOHIRIN
B15: Calon istri | E15: : | F15: ='ISIAN DATA'!H42&" Binti "&'ISIAN DATA'!H51 -> FIKA INTAN ELMASARI Binti SAMIUN
B16: Pada hari | E16: : | F16: ='ISIAN DATA'!H9 -> KAMIS, 19 NOVEMBER 2026 | G16: ='ISIAN DATA'!C10 -> JAM : 08:30 | H16: WIB
B17: Bertempat di | E17: : | F17: ='ISIAN DATA'!H11 -> DSN SIMADU RT 003 RW 008 DESA BADAK KECAMATAN BELIK KABUPATEN PEMALANG
B19: Bersama ini kami sampaikan surat-surat yang diperlukan untuk diperiksa sebagai berikut :
B20: A. Berkas Utama :
C21: 1. | D21: Surat pengantar pernikahan dari Desa/ Kelurahan calon pengantin Putra
D22: (Diurutkan dari N1, N5, AC Asli, Berkas Khusus TNI/ Polri dan Rekomendasi)
C23: 2. | D23: Surat Pengantar Pernikahan dari Desa/ Kelurahan Calon Pengantin Putri
D24: (Diurutkan dari N1, N5, AC Asli, Berkas Khusus TNI/Polri dan Rekomendasi)
C25: 3. | D25: Surat Persetujuan Mempelai (Model N4)
C26: 4. | D26: Asli Putusan Dispensasi Umur dari Pengadilan Agama
C27: 5. | D27: Pasfoto ukuran 2x3 = 2 lembar dan 4x6= 1 lembar berlatar belakang biru
B29: B. Berkas Operator
C30: 1. | D30: Rekam Data Sementara Calon Pengantin
C31: 2. | D31: Surat Keterangan Wali dan Pernyataannya
C32: 3. | D32: Fotocopy Akte Kelahiran dan Ijazah
C33: 4. | D33: Fotocopy KTP, Catin Putra, Catin Putri, Wali
C34: 5. | D34: Fotocopy Kartu Keluarga Catin Putra, Catin Putri, Wali
B36: Demikian permohonan ini kami sampaikan, kiranya dapat diperiksa, dihadiri dan dicatat sesuai dengan ketentuan peraturan perundang-undangan.
B38: Wassalamualaikum Warahmatullahi Wabarakatuh
B40: ="Diterima tanggal ……………..……… "&RIGHT(H5,4) -> Diterima tanggal ……………..……… 2026
B41: Yang menerima,
B42: Kepala KUA/ Penghulu | G42: Pemohon,
B46: ….............................. | G46: =PROPER('ISIAN DATA'!H42) -> Fika Intan Elmasari
G49: Petugas Pengantar,
G53: ='ISIAN DATA'!C6 -> Chalim Muchtarom, S.Pd.I

Sheet N1-Putra
B1: Konsep Cetak Model N1 - Catin Putra | G1: << Menu Utama
C6: PEMERINTAH KABUPATEN PEMALANG
C7: KECAMATAN WATUKUMPUL
C8: ="DESA "&'ISIAN DATA'!C3 -> DESA TAMBI
G9: Model N1
C10: PENGANTAR NIKAH
C11: ="Nomor : "&'ISIAN DATA'!H7 -> Nomor : 400.12.3.2/19/X/2026
C13: Yang bertanda tangan di bawah ini menjelaskan dengan sesungguhnya bahwa:
C14: 1. | D14: Nama | F14: : | G14: ='ISIAN DATA'!H14 -> AOFA ARDIAN FADILLAH AZIZ
C15: 2. | D15: Nomor Induk Kependudukan (NIK) | F15: : | G15: ='ISIAN DATA'!H15 -> 3327041308020004
C16: 3. | D16: Jenis Kelamin | F16: : | G16: LAKI-LAKI
C17: 4. | D17: Tempat dan tanggal lahir | F17: : | G17: ='ISIAN DATA'!H16 -> PEMALANG, 13 AGUSTUS 2002
C18: 5. | D18: Kewarganegaraan | F18: : | G18: INDONESIA
C19: 6. | D19: Agama | F19: : | G19: ISLAM
C20: 7. | D20: Pekerjaan | F20: : | G20: ='ISIAN DATA'!H17 -> WIRASWASTA
C21: 8. | D21: Alamat | F21: : | G21: ='ISIAN DATA'!H20 -> DK. TAMBI RT 002 RW 001 TAMBI
G22: ='ISIAN DATA'!H21 -> KEC. WATUKUMPUL KAB. PEMALANG
C23: 9. | E23: Status pernikahan
D24: a. | E24: Laki-laki; Jejaka, Duda | F24: : | G24: ='ISIAN DATA'!H19 -> JEJAKA (BELUM KAWIN)
E25: atau beristri ke ….... | F25: : | G25: ='ISIAN DATA'!I19
D26: b. | E26: Peremuan: Perawan, Janda
C28: Adalah benar-benar anak dari pernikahan seorang pria:
C30: Nama lengkap dan alias | F30: : | G30: ='ISIAN DATA'!H23 -> TOHIRIN
C31: Nomor Induk Kependudukan (NIK) | F31: : | G31: ='ISIAN DATA'!H24 -> 3327040107730222
C32: Tempat dan tanggal lahir | F32: : | G32: ='ISIAN DATA'!H25 -> PEMALANG, 1 JULI 1973
C33: Kewarganegaraan | F33: : | G33: ='ISIAN DATA'!H26 -> INDONESIA
C34: Agama | F34: : | G34: ='ISIAN DATA'!H27 -> ISLAM
C35: Pekerjaan | F35: : | G35: ='ISIAN DATA'!H28 -> WIRASWASTA
C36: Alamat | F36: : | G36: ='ISIAN DATA'!H29 -> DK. TAMBI RT 002 RW 001 TAMBI
G37: ='ISIAN DATA'!H30 -> KEC. WATUKUMPUL KAB. PEMALANG
C39: Dengan seorang wanita :
C40: Nama lengkap dan alias | F40: : | G40: ='ISIAN DATA'!H32 -> KARIPAH
C41: Nomor Induk Kependudukan (NIK) | F41: : | G41: ='ISIAN DATA'!H33 -> 3327044107740064
C42: Tempat dan tanggal lahir | F42: : | G42: ='ISIAN DATA'!H34 -> PEMALANG, 1 JULI 1974
C43: Kewarganegaraan | F43: : | G43: ='ISIAN DATA'!H35 -> INDONESIA
C44: Agama | F44: : | G44: ='ISIAN DATA'!H36 -> ISLAM
C45: Pekerjaan | F45: : | G45: ='ISIAN DATA'!H37 -> MENGURUS RUMAH TANGGA
C46: Alamat | F46: : | G46: ='ISIAN DATA'!H38 -> DK. TAMBI RT 002 RW 001 TAMBI
G47: ='ISIAN DATA'!H39 -> KEC. WATUKUMPUL KAB. PEMALANG
C49: Demikian surat pengantar ini dibuat dengan mengingat sumpah jabatan dan untuk dipergunakan sebagaimana mestinya
...

Sheet N1-Putri
B1: Konsep Cetak Model N1 - Catina Putri | G1: << Menu Utama
C6: PEMERINTAH KABUPATEN PEMALANG
C7: KECAMATAN WATUKUMPUL
C8: ="DESA "&'ISIAN DATA'!C3 -> DESA TAMBI
G9: Model N1
C10: PENGANTAR NIKAH
C11: ="Nomor : "&'ISIAN DATA'!H7 -> Nomor : 400.12.3.2/19/X/2026
C13: Yang bertanda tangan di bawah ini menjelaskan dengan sesungguhnya bahwa:
C14: 1. | D14: Nama | F14: : | G14: ='ISIAN DATA'!H42 -> FIKA INTAN ELMASARI
C15: 2. | D15: Nomor Induk Kependudukan (NIK) | F15: : | G15: ='ISIAN DATA'!H43 -> 3327034810050002
C16: 3. | D16: Jenis Kelamin | F16: : | G16: PEREMPUAN
C17: 4. | D17: Tempat dan tanggal lahir | F17: : | G17: ='ISIAN DATA'!H44 -> PEMALANG, 8 OKTOBER 2005
C18: 5. | D18: Kewarganegaraan | F18: : | G18: ='ISIAN DATA'!H46 -> INDONESIA
C19: 6. | D19: Agama | F19: : | G19: ISLAM
C20: 7. | D20: Pekerjaan | F20: : | G20: ='ISIAN DATA'!H45 -> PELAJAR MAHASISWA
C21: 8. | D21: Alamat | F21: : | G21: ='ISIAN DATA'!H48 -> DSN SIMADU RT 003 RW 008 DESA BADAK
G22: ='ISIAN DATA'!H49 -> KECAMATAN BELIK KABUPATEN PEMALANG
C23: 9. | E23: Status pernikahan
D24: a. | E24: Laki-laki; Jejaka, Duda
E25: atau beristri ke …....
D26: b. | E26: Peremuan: Perawan, Janda | F26: : | G26: ='ISIAN DATA'!H47 -> PERAWAN (BELUM KAWIN)
C28: Adalah benar-benar anak dari pernikahan seorang pria:
C30: Nama lengkap dan alias | F30: : | G30: ='ISIAN DATA'!H51 -> SAMIUN
C31: Nomor Induk Kependudukan (NIK) | F31: : | G31: ='ISIAN DATA'!H52 -> 3327031103810011
C32: Tempat dan tanggal lahir | F32: : | G32: ='ISIAN DATA'!H53 -> PEMALANG, 11 MARET 1981
C33: Kewarganegaraan | F33: : | G33: ='ISIAN DATA'!H54 -> INDONESIA
C34: Agama | F34: : | G34: ='ISIAN DATA'!H55 -> ISLAM
C35: Pekerjaan | F35: : | G35: ='ISIAN DATA'!H56 -> PETANI
C36: Alamat | F36: : | G36: ='ISIAN DATA'!H57 -> DSN SIMADU RT 003 RW 008 DESA BADAK
G37: ='ISIAN DATA'!H58 -> KECAMATAN BELIK KABUPATEN PEMALANG
C39: Dengan seorang wanita :
C40: Nama lengkap dan alias | F40: : | G40: ='ISIAN DATA'!H60 -> SRINANI
C41: Nomor Induk Kependudukan (NIK) | F41: : | G41: ='ISIAN DATA'!H61 -> 3327034101870012
C42: Tempat dan tanggal lahir | F42: : | G42: ='ISIAN DATA'!H62 -> PEMALANG, 1 JANUARI 1987
C43: Kewarganegaraan | F43: : | G43: ='ISIAN DATA'!H63 -> INDONESIA
C44: Agama | F44: : | G44: ='ISIAN DATA'!H64 -> ISLAM
C45: Pekerjaan | F45: : | G45: ='ISIAN DATA'!H65 -> MENGURUS RUMAH TANGGA
C46: Alamat | F46: : | G46: ='ISIAN DATA'!H66 -> DSN SIMADU RT 003 RW 008 DESA BADAK
G47: ='ISIAN DATA'!H67 -> KECAMATAN BELIK KABUPATEN PEMALANG
C49: Demikian surat pengantar ini dibuat dengan mengingat sumpah jabatan dan untuk dipergunakan sebagaimana mestinya
...

Sheet N4
B1: Lembar Persetujuan | D1: << Menu Utama
B2: Penyesuaian Lampiran VIII
B3: Keputusan Dirjen Bimas Islam Nomor 473 Tahun 2020
B4: Model N4
B6: PERSETUJUAN CALON PENGANTIN
B8: Yang bertanda tangan di bawah ini :
B9: A. | C9: Calon Suami:
C10: 1. Nama lengkap dan alias | D10: ='ISIAN DATA'!H14 -> AOFA ARDIAN FADILLAH AZIZ
C11: 2. Bin | D11: =UPPER('ISIAN DATA'!J23) -> TOHIRIN
C12: 3. Nomor Induk Kependudukan | D12: ='ISIAN DATA'!H15 -> 3327041308020004
C13: 4. Tempat dan tanggal lahir | D13: ='ISIAN DATA'!H16 -> PEMALANG, 13 AGUSTUS 2002
C14: 5. Kewarganegaraan | D14: ='ISIAN DATA'!H18 -> INDONESIA
C15: 6. Agama | D15: ISLAM
C16: 7. Pekerjaan | D16: ='ISIAN DATA'!H17 -> WIRASWASTA
C17: 8. Alamat | D17: ='ISIAN DATA'!H20 -> DK. TAMBI RT 002 RW 001 TAMBI
D18: ='ISIAN DATA'!H21 -> KEC. WATUKUMPUL KAB. PEMALANG
B20: B. | C20: Calon Istri:
C21: 1. Nama lengkap dan alias | D21: ='ISIAN DATA'!H42 -> FIKA INTAN ELMASARI
C22: 2. Binti | D22: =UPPER('ISIAN DATA'!J51) -> SAMIUN
C23: 3. Nomor Induk Kependudukan | D23: ='ISIAN DATA'!H43 -> 3327034810050002
C24: 4. Tempat dan tanggal lahir | D24: ='ISIAN DATA'!H44 -> PEMALANG, 8 OKTOBER 2005
C25: 5. Kewarganegaraan | D25: ='ISIAN DATA'!H46 -> INDONESIA
C26: 6. Agama | D26: ISLAM
C27: 7. Pekerjaan | D27: ='ISIAN DATA'!H45 -> PELAJAR MAHASISWA
C28: 8. Alamat | D28: ='ISIAN DATA'!H48 -> DSN SIMADU RT 003 RW 008 DESA BADAK
D29: ='ISIAN DATA'!H49 -> KECAMATAN BELIK KABUPATEN PEMALANG
B31: Menyatakan dengan sesungguhnya bahwa atas dasar suka rela, dengan kesadaran sendiri, tanpa ada paksaan dari siapapun juga, setuju untuk melangsungkan pernikahan.
B33: Demikian surat persetujuan ini dibuat untuk digunakan seperlunya.
D35: ='ISIAN DATA'!H8 -> Tambi, 08 Oktober 2026
C37: Calon Suami, | D37: Calon Istri,
B41: =PROPER(D10) -> Aofa Ardian Fadillah Aziz | D41: =PROPER(D21) -> Fika Intan Elmasari

Sheet N5
E1: << Menu Utama | L1: _____________________
B2: Pilih cetak Surat Izin (N5) ---->>> | E2: Calon SUAMI | G2: =IF(J5=4,4,IF(E2="Calon Suami",1,IF(E2="Calon Istri",2,4))) -> #NAME? | L2: ______________________________________
B5: Model N5 | J5: =I6+I7 -> #NAME? | K5: =IF(J5=1,K8,IF(J5=3,K8,IF(J5=2,L8,"NIHIL"))) -> #NAME?
B6: SURAT IZIN ORANG TUA/ PENGAMPU | I6: {=_xlfn.IFS(K7="11",1,K7="12",1,K7="13",1,K7="14",1,K7="15",1,K7="16",1,K7="17",1,K7="18",1,K7="19",1,K7="20",1,K7<>"","0")} -> #NAME? | K6: =IF(J5=3,L8,"") -> #NAME?
I7: {=_xlfn.IFS(L7="11",2,L7="12",2,L7="13",2,L7="14",2,L7="15",2,L7="16",2,L7="17",2,L7="18",2,L7="19",2,L7="20",2,L7<>"","0")} -> #NAME? | K7: ='ISIAN DATA'!J17 -> 24 | L7: ='ISIAN DATA'!J45 -> 20
B8: Yang bertanda tangan di bawah ini: | K8: Calon SUAMI | L8: Calon ISTRI
B10: A. | C10: 1. Nama lengkap dan alias | D10: : | E10: =IF($G$2=1,K10,IF($G$2=2,L10,"TIDAK ADA DATA")) -> #NAME? | G10: 1 | H10: Pa-Pi | I10: 2 | K10: =IF($I$32=0,L2,'ISIAN DATA'!H23) -> TOHIRIN | L10: =IF($I$43=0,L2,'ISIAN DATA'!H51) -> SAMIUN
C11: 2. Bin | D11: : | E11: =IF($G$2=1,K11,IF($G$2=2,L11,"-")) -> #NAME? | G11: 2 | H11: Pi | I11: > | K11: =IF($I$32=0,L2,PROPER('ISIAN DATA'!D23)) -> Muhayat | L11: =IF($I$43=0,L2,PROPER('ISIAN DATA'!D51)) -> Wasnuri
C12: 3. Nomor Induk Kependudukan | D12: : | E12: =IF($G$2=1,K12,IF($G$2=2,L12,"-")) -> #NAME? | G12: 3 | H12: Pa | I12: > | K12: =IF($I$32=0,L2,PROPER('ISIAN DATA'!H24)) -> 3327040107730222 | L12: =IF($I$43=0,L2,PROPER('ISIAN DATA'!H52)) -> 3327031103810011
C13: 4. Tempat dan tanggal lahir | D13: : | E13: =IF($G$2=1,K13,IF($G$2=2,L13,"-")) -> #NAME? | G13: 4 | H13: Nihil | I13: 4 | K13: =IF($I$32=0,L2,PROPER('ISIAN DATA'!H25)) -> Pemalang, 1 Juli 1973 | L13: =IF($I$43=0,L2,PROPER('ISIAN DATA'!H53)) -> Pemalang, 11 Maret 1981
C14: 5. Kewarganegaraan | D14: : | E14: =IF($G$2=1,K14,IF($G$2=2,L14,"-")) -> #NAME? | K14: =IF($I$32=0,"Indonesia",PROPER('ISIAN DATA'!H26)) -> Indonesia | L14: =IF($I$43=0,"Indonesia",PROPER('ISIAN DATA'!H54)) -> Indonesia
C15: 6. Agama | D15: : | E15: =IF($G$2=1,K15,IF($G$2=2,L15,"-")) -> #NAME? | K15: =IF($I$32=0,"Islam",PROPER('ISIAN DATA'!H27)) -> Islam | L15: =IF($I$43=0,"Islam",PROPER('ISIAN DATA'!H55)) -> Islam
C16: 7. Pekerjaan | D16: : | E16: =IF($G$2=1,K16,IF($G$2=2,L16,"-")) -> #NAME? | K16: =IF($I$32=0,L2,PROPER('ISIAN DATA'!H28)) -> Wiraswasta | L16: =IF($I$43=0,L2,PROPER('ISIAN DATA'!H56)) -> Petani
C17: 8. Alamat | D17: : | E17: =IF($G$2=1,K17,IF($G$2=2,L17,"-")) -> #NAME? | K17: =IF($I$32=0,L2,PROPER('ISIAN DATA'!H29)) -> Dk. Tambi Rt 002 Rw 001 Tambi | L17: =IF($I$43=0,L2,PROPER('ISIAN DATA'!H57)) -> Dsn Simadu Rt 003 Rw 008 Desa Badak
E18: =IF($G$2=1,K18,IF($G$2=2,L18,"-")) -> #NAME? | K18: =IF($I$32=0,L2,PROPER('ISIAN DATA'!H30)) -> Kec. Watukumpul Kab. Pemalang | L18: =IF($I$43=0,L2,PROPER('ISIAN DATA'!H58)) -> Kecamatan Belik Kabupaten Pemalang
B20: B. | C20: 1. Nama lengkap dan alias | D20: : | E20: =IF($G$2=1,K20,IF($G$2=2,L20,"TIDAK ADA DATA")) -> #NAME? | K20: =IF($J$32=0,L2,'ISIAN DATA'!H32) -> KARIPAH | L20: =IF($J$43=0,L2,'ISIAN DATA'!H60) -> SRINANI
C21: 2. Binti | D21: : | E21: =IF($G$2=1,K21,IF($G$2=2,L21,"-")) -> #NAME? | K21: =IF($J$32=0,L2,PROPER('ISIAN DATA'!D32)) -> Sumarto | L21: =IF($J$43=0,L2,PROPER('ISIAN DATA'!D60)) -> Sahron
C22: 3. Nomor Induk Kependudukan | D22: : | E22: =IF($G$2=1,K22,IF($G$2=2,L22,"-")) -> #NAME? | K22: =IF($J$32=0,L2,PROPER('ISIAN DATA'!H33)) -> 3327044107740064 | L22: =IF($J$43=0,L2,PROPER('ISIAN DATA'!H61)) -> 3327034101870012
C23: 4. Tempat dan tanggal lahir | D23: : | E23: =IF($G$2=1,K23,IF($G$2=2,L23,"-")) -> #NAME? | K23: =IF($J$32=0,L2,PROPER('ISIAN DATA'!H34)) -> Pemalang, 1 Juli 1974 | L23: =IF($J$43=0,L2,PROPER('ISIAN DATA'!H62)) -> Pemalang, 1 Januari 1987
C24: 5. Kewarganegaraan | D24: : | E24: =IF($G$2=1,K24,IF($G$2=2,L24,"-")) -> #NAME? | K24: =IF($J$32=0,"Indonesia",PROPER('ISIAN DATA'!H35)) -> Indonesia | L24: =IF($J$43=0,"Indonesia",PROPER('ISIAN DATA'!H63)) -> Indonesia
C25: 6. Agama | D25: : | E25: =IF($G$2=1,K25,IF($G$2=2,L25,"-")) -> #NAME? | K25: =IF($J$32=0,"Islam",PROPER('ISIAN DATA'!H36)) -> Islam | L25: =IF($J$43=0,"Islam",PROPER('ISIAN DATA'!H64)) -> Islam
C26: 7. Pekerjaan | D26: : | E26: =IF($G$2=1,K26,IF($G$2=2,L26,"-")) -> #NAME? | K26: =IF($J$32=0,L2,PROPER('ISIAN DATA'!H37)) -> Mengurus Rumah Tangga | L26: =IF($J$43=0,L2,PROPER('ISIAN DATA'!H65)) -> Mengurus Rumah Tangga
C27: 8. Alamat | D27: : | E27: =IF($G$2=1,K27,IF($G$2=2,L27,"-")) -> #NAME? | K27: =IF($J$32=0,L2,PROPER('ISIAN DATA'!H38)) -> Dk. Tambi Rt 002 Rw 001 Tambi | L27: =IF($J$43=0,L2,PROPER('ISIAN DATA'!H66)) -> Dsn Simadu Rt 003 Rw 008 Desa Badak
E28: =IF($G$2=1,K28,IF($G$2=2,L28,"-")) -> #NAME? | K28: =IF($J$32=0,L2,PROPER('ISIAN DATA'!H39)) -> Kec. Watukumpul Kab. Pemalang | L28: =IF($J$43=0,L2,PROPER('ISIAN DATA'!H67)) -> Kecamatan Belik Kabupaten Pemalang
C30: adalah ayah dan ibu kandung/ wali/ pengampu dari :
C31: 1. Nama lengkap dan alias | D31: : | E31: =IF($G$2=1,K31,IF($G$2=2,L31,"Hey, Mau cetak apa?")) -> #NAME? | H31: =IF($G$2=1,I31,J31) -> #NAME? | I31: Pa | J31: Pi | K31: ='ISIAN DATA'!H14 -> AOFA ARDIAN FADILLAH AZIZ | L31: ='ISIAN DATA'!H42 -> FIKA INTAN ELMASARI
C32: =H32 -> #NAME? | D32: : | E32: =IF($G$2=1,K32,IF($G$2=2,L32,"-")) -> #NAME? | H32: =IF(H31="Pa","2. Bin","2. Binti") -> #NAME? | I32: ='ISIAN DATA'!G23 -> 1 | J32: ='ISIAN DATA'!G32 -> 1 | K32: ='ISIAN DATA'!J23 -> Tohirin | L32: ='ISIAN DATA'!J51 -> Samiun
C33: 3. Nomor Induk Kependudukan | D33: : | E33: =IF($G$2=1,K33,IF($G$2=2,L33,"-")) -> #NAME? | I33: =IF(I32=1,"Ayah,","Pengampu I") -> Ayah, | J33: =IF(J32=1,"Ibu,","Pengampu II") -> Ibu, | K33: =PROPER('ISIAN DATA'!H15) -> 3327041308020004 | L33: =PROPER('ISIAN DATA'!H43) -> 3327034810050002
C34: 4. Tempat dan tanggal lahir | D34: : | E34: =IF($G$2=1,K34,IF($G$2=2,L34,"-")) -> #NAME? | I34: =IF(I32=1,PROPER(K10),L1) -> Tohirin | J34: =IF(J32=1,PROPER(K20),L1) -> Karipah | K34: =PROPER('ISIAN DATA'!H16) -> Pemalang, 13 Agustus 2002 | L34: =PROPER('ISIAN DATA'!H44) -> Pemalang, 8 Oktober 2005
C35: 5. Kewarganegaraan | D35: : | E35: =IF($G$2=1,K35,IF($G$2=2,L35,"-")) -> #NAME? | K35: =PROPER('ISIAN DATA'!H18) -> Indonesia | L35: =PROPER('ISIAN DATA'!H46) -> Indonesia
C36: 6. Agama | D36: : | E36: =IF($G$2=1,K36,IF($G$2=2,L36,"-")) -> #NAME? | K36: Islam | L36: Islam
C37: 7. Pekerjaan | D37: : | E37: =IF($G$2=1,K37,IF($G$2=2,L37,"-")) -> #NAME? | K37: =PROPER('ISIAN DATA'!H17) -> Wiraswasta | L37: =PROPER('ISIAN DATA'!H45) -> Pelajar Mahasiswa
C38: 8. Alamat | D38: : | E38: =IF($G$2=1,K38,IF($G$2=2,L38,"-")) -> #NAME? | K38: =PROPER('ISIAN DATA'!H20) -> Dk. Tambi Rt 002 Rw 001 Tambi | L38: =PROPER('ISIAN DATA'!H48) -> Dsn Simadu Rt 003 Rw 008 Desa Badak
E39: =IF($G$2=1,K39,IF($G$2=2,L39,"-")) -> #NAME? | K39: =PROPER('ISIAN DATA'!H21) -> Kec. Watukumpul Kab. Pemalang | L39: =PROPER('ISIAN DATA'!H49) -> Kecamatan Belik Kabupaten Pemalang
C41: memberikan izin kepada yang bersangkutan untuk melakukan pernikahan dengan :
C42: 1. Nama lengkap dan alias | D42: : | E42: =IF($G$2=1,K42,IF($G$2=2,L42,"Hey, Mau cetak apa?")) -> #NAME? | H42: =IF($G$2=1,J42,I42) -> #NAME? | I42: Pa | J42: Pi | K42: ='ISIAN DATA'!H42 -> FIKA INTAN ELMASARI | L42: ='ISIAN DATA'!H14 -> AOFA ARDIAN FADILLAH AZIZ
C43: =H43 -> #NAME? | D43: : | E43: =IF($G$2=1,K43,IF($G$2=2,L43,"-")) -> #NAME? | H43: =IF(H42="Pa","2. Bin","2. Binti") -> #NAME? | I43: ='ISIAN DATA'!G51 -> 1 | J43: ='ISIAN DATA'!G60 -> 1 | K43: ='ISIAN DATA'!J51 -> Samiun | L43: ='ISIAN DATA'!J23 -> Tohirin
C44: 3. Nomor Induk Kependudukan | D44: : | E44: =IF($G$2=1,K44,IF($G$2=2,L44,"-")) -> #NAME? | I44: =IF(I43=1,"Ayah,","Pengampu I") -> Ayah, | J44: =IF(J43=1,"Ibu,","Pengampu II") -> Ibu, | K44: =PROPER('ISIAN DATA'!H43) -> 3327034810050002 | L44: =PROPER('ISIAN DATA'!H15) -> 3327041308020004
C45: 4. Tempat dan tanggal lahir | D45: : | E45: =IF($G$2=1,K45,IF($G$2=2,L45,"-")) -> #NAME? | I45: =IF(I43=1,PROPER(L10),L1) -> Samiun | J45: =IF(J43=1,PROPER(L20),L1) -> Srinani | K45: =PROPER('ISIAN DATA'!H44) -> Pemalang, 8 Oktober 2005 | L45: =PROPER('ISIAN DATA'!H16) -> Pemalang, 13 Agustus 2002
C46: 5. Kewarganegaraan | D46: : | E46: =IF($G$2=1,K46,IF($G$2=2,L46,"-")) -> #NAME? | K46: =PROPER('ISIAN DATA'!H46) -> Indonesia | L46: =PROPER('ISIAN DATA'!H18) -> Indonesia
...

Sheet SKW
E1: << Menu Utama
B5: PEMERINTAH KABUPATEN PEMALANG
B6: KECAMATAN WATUKUMPUL
B7: ="DESA "&'ISIAN DATA'!H3 -> DESA TAMBI
B9: SURAT KETERANGAN WALI
B10: ="Nomor : "&'ISIAN DATA'!H7 -> Nomor : 400.12.3.2/19/X/2026
B12: Yang bertanda tangan di bawah ini, menerangkan dengan sesungguhnya bahwa calon pengantin:
B14: 1. | C14: Nama Calon Suami | D14: ='ISIAN DATA'!H14 -> AOFA ARDIAN FADILLAH AZIZ
C15: Bin | D15: ='ISIAN DATA'!J23 -> Tohirin | E15: ="NIK : "&'ISIAN DATA'!H15 -> NIK : 3327041308020004
C16: Tempat Tanggal Lahir | D16: =PROPER('ISIAN DATA'!H16) -> Pemalang, 13 Agustus 2002
C17: Kewarganegaraan | D17: =PROPER('ISIAN DATA'!H18) -> Indonesia | E17: Agama : ISLAM
C18: Alamat | D18: =PROPER(('ISIAN DATA'!H20)) -> Dk. Tambi Rt 002 Rw 001 Tambi
D19: =PROPER('ISIAN DATA'!H21) -> Kec. Watukumpul Kab. Pemalang
B21: 2. | C21: Nama Calon Istri | D21: ='ISIAN DATA'!H42 -> FIKA INTAN ELMASARI
C22: Binti | D22: ='ISIAN DATA'!J51 -> Samiun | E22: ="NIK : "&'ISIAN DATA'!H43 -> NIK : 3327034810050002
C23: Tempat Tanggal Lahir | D23: =PROPER('ISIAN DATA'!H44) -> Pemalang, 8 Oktober 2005
C24: Kewarganegaraan | D24: =PROPER('ISIAN DATA'!H46) -> Indonesia | E24: Agama : ISLAM
C25: Alamat | D25: =PROPER('ISIAN DATA'!H48) -> Dsn Simadu Rt 003 Rw 008 Desa Badak
D26: =PROPER('ISIAN DATA'!H49) -> Kecamatan Belik Kabupaten Pemalang
B28: ="akan melaksanakan akad nikah pada hari "&'ISIAN DATA'!H10&" dengan menggunakan "&'ISIAN DATA'!H70 -> akan melaksanakan akad nikah pada hari Kamis, 19 November 2026 dengan menggunakan WALI NASAB
B30: A. | C30: WALI NASAB
C31: Nama Wali | D31: ='ISIAN DATA'!H75 -> SAMIUN
C32: BIN | D32: =PROPER('ISIAN DATA'!H76) -> Wasnuri
C33: NIK | D33: =PROPER('ISIAN DATA'!H77) -> 3327031103810011
C34: Tempat Tanggal Lahir | D34: =PROPER('ISIAN DATA'!H78) -> Pemalang, 11 Maret 1981
C35: Kewarganegaraan/Agama | D35: =PROPER('ISIAN DATA'!H79) -> Indonesia
C36: Pekerjaan | D36: =PROPER('ISIAN DATA'!H81) -> Petani
C37: Alamat | D37: =PROPER('ISIAN DATA'!H82) -> Dsn Simadu Rt 003 Rw 008 Desa Badak
D38: =PROPER('ISIAN DATA'!H83) -> Kecamatan Belik Kabupaten Pemalang
C39: Hubungan | D39: ='ISIAN DATA'!H71 -> AYAH KANDUNG
C41: Ayah Kandung | D41: Paman Kandung | E41: Paman Ayah Seayah
C42: Kakek | D42: Paman Seayah | E42: Anak Paman Ayah Kandung
C43: Buyut | D43: Anak Paman Kandung | E43: Anak Paman Ayah Seayah
C44: Saudara Sekandung | D44: Anak Paman Seayah | E44: Paman Kakek Kandung
C45: Saudara Seayah | D45: Cucu Paman Kandung | E45: Paman Kakek Seayah
C46: Anak Saudara Sekandung | D46: Cucu Paman Seayah | E46: Anak Paman Kakek Kandung
C47: Anak Saudara Seayah | D47: Paman Ayah Kandung | E47: Anak Paman Kakek Seayah
B49: B. | C49: WALI HAKIM
C50: Alasan / Sebab Wali Hakim | D50: ='ISIAN DATA'!H72 -> -
B52: Demikian keterangan ini dibuat dengan sebenar-benarnya untuk menjadi maklum dan digunakan sebagaimana mestinya.
...

Sheet Super WH
B2: Pilih wali aqrab terakhir -->>> | C2: PAMAN AYAH (SEAYAH)
B4: SURAT PERNYATAAN
B5: Permohonan Pernikahan Menggunakan Wali Hakim
B7: Bismillahirrahmanirrahim
B8: =" Pada hari ini "&F10&", yang bertanda tangan di bawah ini selaku calon pengantin perempuan menyatakan dengan sebenar-benarnya, bahwa saya: " -> Pada hari ini Kamis, 8 Oktober 2026, yang bertanda tangan di bawah ini selaku calon pengantin perempuan menyatakan dengan sebenar-benarnya, bahwa saya: | F8: ='ISIAN DATA'!C8 -> 46303
B10: Nama | C10: ='ISIAN DATA'!H42 -> FIKA INTAN ELMASARI | F10: =TEXT(F8," Dddd, d mmmm yyyy") -> Kamis, 8 Oktober 2026
B11: Binti | C11: =IF(G22=1,"-",PROPER('ISIAN DATA'!H51)) -> Samiun
B12: NIK | C12: =IF(G21=1,"-",PROPER('ISIAN DATA'!H43)) -> 3327034810050002
B13: Tempat, tanggal lahir | C13: =IF(G21=1,"-",PROPER('ISIAN DATA'!H44)) -> Pemalang, 8 Oktober 2005 | F13: ='ISIAN DATA'!H72 -> -
B14: Kewarganegaraan | C14: =IF(G21=1,"-",SKW!D24&" Agama : Islam") -> Indonesia Agama : Islam | F14: Telah meninggal dunia sehingga menjadi:
B15: Pekerjaan | C15: =IF(G21=1,"-",PROPER('ISIAN DATA'!H45)) -> Pelajar Mahasiswa | F15: =IF(F13="HABIS BARIS WALI",(F14&F13),F13) -> -
B16: Alamat | C16: =IF(G21=1,"-",PROPER('ISIAN DATA'!H48)) -> Dsn Simadu Rt 003 Rw 008 Desa Badak
C17: =IF(G21=1,"-",PROPER('ISIAN DATA'!H49)) -> Kecamatan Belik Kabupaten Pemalang
B19: 1. Setelah ditelusuri dengan seksama ketersambungan wali aqrab saya jatuh pada: | F19: SEPI WALI | G19: =IF(F19=F13,1,0) -> 0
B20: =IF(G21=1,"-",(" "&C2)) -> PAMAN AYAH (SEAYAH) | F20: WALI ADHAL (PUTUSAN PENGADILAN AGAMA) | G20: =IF(F20=F13,1,0) -> 0
B21: 2. Wali dimakdud pada nomor 1 (satu) dalam keadaan: | G21: =SUM(G19:G20) -> 0
B22: =IF(G21=1,"-",(" "&F15)) -> -
B23: =" "&"Oleh karena itu saya mohon dengan hormat, kepada Kepala KUA Watukumpul Kabupaten Pemalang, untuk bertindak sebagai wali hakim atas pernikahan saya dengan seorang laki-laki bernama "&'ISIAN DATA'!H14&" Bin "&'ISIAN DATA'!H23&" pada:" -> Oleh karena itu saya mohon dengan hormat, kepada Kepala KUA Watukumpul Kabupaten Pemalang, untuk bertindak sebagai wali hakim atas pernikahan saya dengan seorang laki-laki bernama AOFA ARDIAN FADILLAH AZIZ Bin TOHIRIN pada:
U24: Saksi II
B25: Hari/ tanggal | C25: =IF(G21=1,"-",PROPER('ISIAN DATA'!H9)) -> Kamis, 19 November 2026
B26: Waktu | C26: =IF(G21=1,"-",PROPER('ISIAN DATA'!C10)&" WIB") -> Jam : 08:30 WIB
B27: Lokasi akad nikah | C27: {=IF(G21=1,"-",PROPER('ISIAN DATA'!C11:D11))} -> Dsn Simadu Rt 003 Rw 008 Desa Badak Kecamatan Belik Kabupaten Pemalang | U27: Nama saksi
B29: Demikian pernyataan ini saya buat dengan penuh kesadaran tanpa paksaan pihak manapun, dan saya siap menerima akibat hukum apapun jika pernyataan ini tidak sesuai keadaan sebenarnya.
C31: Yang menyatakan, | Q31: Kepala Desa
C33: Meterai 10K
C35: =C10 -> FIKA INTAN ELMASARI
B37: Saksi Kesatu, | C37: Saksi Kedua,
B41: TARMIN | C41: TUSAM
Q42: Nama Kepala Desa
C43: << Menu Utama

Sheet Dispensasi
B1: Cetak Permohonan Dispensasi Kurang 10 hari Kerja
E2: << Menu Utama
B6: PEMERINTAH KABUPATEN PEMALANG
B7: KECAMATAN WATUKUMPUL
B8: ="DESA "&'ISIAN DATA'!H3 -> DESA TAMBI
B10: Nomor | C10: ='ISIAN DATA'!H7 -> 400.12.3.2/19/X/2026 | E10: ='ISIAN DATA'!H8 -> Tambi, 08 Oktober 2026
B11: Lamp. | C11: -
B12: Perihal | C12: Permohonan Dispensasi
E15: Kepada Yth.
E16: Camat Watukumpul
E17: di WATUKUMPUL
B20: =" "&"Berdasarkan permohonan kehendak nikah calon pengantin dan Pengantar Nikah dari Kepala Desa "&PROPER('ISIAN DATA'!H3)&", calon pasangan pengantin tersebut di bawah ini:" -> Berdasarkan permohonan kehendak nikah calon pengantin dan Pengantar Nikah dari Kepala Desa Tambi, calon pasangan pengantin tersebut di bawah ini:
B22: Calon Istri
B23: Nama | D23: =IF(D48="","-",'ISIAN DATA'!H42) -> -
B24: NIK | D24: ='ISIAN DATA'!H43 -> 3327034810050002
B25: Tempat, Tgl Lahir | D25: ='ISIAN DATA'!H44 -> PEMALANG, 8 OKTOBER 2005
B26: Warganegara | D26: ='ISIAN DATA'!H46 -> INDONESIA
B27: Agama | D27: Islam
B28: Pekerjaan | D28: =IF(D48="","-",(PROPER('ISIAN DATA'!H45))) -> -
B29: Alamat | D29: =IF(D48="","-",(PROPER('ISIAN DATA'!H48))) -> -
D30: =IF(D48="","-",(PROPER('ISIAN DATA'!H49))) -> -
B31: Nama Ayah | D31: ='ISIAN DATA'!H51 -> SAMIUN
B32: Nama Ibu | D32: ='ISIAN DATA'!H60 -> SRINANI
B34: Calon Suami
B35: Nama | D35: =IF(D48="","-",'ISIAN DATA'!H14) -> -
B36: NIK | D36: ='ISIAN DATA'!H15 -> 3327041308020004
B37: Tempat, Tgl Lahir | D37: =PROPER('ISIAN DATA'!H16) -> Pemalang, 13 Agustus 2002
B38: Warganegara | D38: =PROPER('ISIAN DATA'!H18) -> Indonesia
B39: Agama | D39: Islam
B40: Pekerjaan | D40: =IF(D48="","-",(PROPER('ISIAN DATA'!H17))) -> -
B41: Alamat | D41: =IF(D48="","-",(PROPER('ISIAN DATA'!H20))) -> -
D42: =IF(D48="","-",(PROPER('ISIAN DATA'!H21))) -> -
B43: Nama Ayah | D43: ='ISIAN DATA'!H23 -> TOHIRIN
B44: Nama Ibu | D44: ='ISIAN DATA'!H32 -> KARIPAH
B46: Waktu Pelaksanaan dan Alasan Dispensasi
B47: Waktu | D47: =IF(D48="","-",(PROPER('ISIAN DATA'!H9))) -> -
B48: Alasan | D48: ='ISIAN DATA'!I10
B50: dengan hormat memohon agar Camat Watukumpul berkenan memberikan dispensasi pendaftaran nikah untuk pelaksanan kurang dari 10 (sepuluh) hari kerja.
B52: Demikian permohonan dispensasi ini disampaikan untuk menjadikan maklum dan guna seperlunya.
E54: Kepala Desa,
...

Sheet Kendali
A1: Lembar Kendali | E1: << Menu Utama
B3: LEMBAR KENDALI IJAB QABUL
B4: KUA WATUKUMPUL
B5: =======================================
B6: Pengantar | C6: =RDS!F59 -> Chalim Muchtarom, S.Pd.I | E6: ="Desa : "&PROPER('ISIAN DATA'!H3) -> Desa : Tambi
B7: Waktu | C7: ='ISIAN DATA'!H9 -> KAMIS, 19 NOVEMBER 2026 | E7: =RDS!H6 -> Jam : 08:30 WIB
B8: Lokasi | C8: ='ISIAN DATA'!H11 -> DSN SIMADU RT 003 RW 008 DESA BADAK KECAMATAN BELIK KABUPATEN PEMALANG
B9: =======================================
B10: ='ISIAN DATA'!H14 -> AOFA ARDIAN FADILLAH AZIZ | E10: ='ISIAN DATA'!J19 -> Jejaka - SLTA
C11: Bin | D11: ='ISIAN DATA'!J23 -> Tohirin
B13: ='ISIAN DATA'!H42 -> FIKA INTAN ELMASARI | E13: ='ISIAN DATA'!J47 -> Perawan - SLTA
C14: Binti | D14: ='ISIAN DATA'!J51 -> Samiun
B16: ='ISIAN DATA'!H70 -> WALI NASAB
C17: =PROPER('ISIAN DATA'!I71) -> Ayah Kandung
C18: =IF('ISIAN DATA'!H70="WALI HAKIM","-",'ISIAN DATA'!I75) -> SAMIUN Bin WASNURI
B20: Maskawin/ Mahar | D20: UANG / ALAT SHALAT/ PERHIASAN EMAS / LOGAM MULIA
D21: RP // _________________ Gram
B24: SAKSI PERTAMA
B25: Nama | D25: ____________________________________________
B26: Tempat, tanggal lahir | D26: ____________________________________________
B27: NIK | D27: ____________________________________________
B28: Pekerjaan | D28: ____________________________________________
B29: Alamat | D29: ____________________________________________
B31: SAKSI KEDUA
B32: Nama | D32: ____________________________________________
B33: Tempat, tanggal lahir | D33: ____________________________________________
B34: NIK | D34: ____________________________________________
B35: Pekerjaan | D35: ____________________________________________
B36: Alamat | D36: ____________________________________________
B39: Catatan lain
E45: Watukumpul,
E46: Petugas Pemeriksa,
E48: ____________________

Sheet RDS Operator
C2: RDS - OPERATOR | F2: << Menu Utama
A5: Mulai Block ---> | C5: ='ISIAN DATA'!H3&"/ "&'ISIAN DATA'!H6 -> TAMBI/ Chalim Muchtarom, S.Pd.I | F5: Blok area TIDAK TERKUNCI dan COPY
C6: ='ISIAN DATA'!H7 -> 400.12.3.2/19/X/2026 | F6: Paste di Note Pad
C7: ='ISIAN DATA'!H9 -> KAMIS, 19 NOVEMBER 2026 | F7: Copy hasil hasil di Note Pad
C8: ='ISIAN DATA'!H11 -> DSN SIMADU RT 003 RW 008 DESA BADAK KECAMATAN BELIK KABUPATEN PEMALANG | F8: Paste di WA dan kirim ke OPERATOR KUA
C9: =============
C10: ='ISIAN DATA'!H14 -> AOFA ARDIAN FADILLAH AZIZ
C11: ='ISIAN DATA'!H15 -> 3327041308020004
C12: ='ISIAN DATA'!H16 -> PEMALANG, 13 AGUSTUS 2002
C13: ='ISIAN DATA'!H17 -> WIRASWASTA
C14: ='ISIAN DATA'!H19 -> JEJAKA (BELUM KAWIN)
C15: ='ISIAN DATA'!H20 -> DK. TAMBI RT 002 RW 001 TAMBI
C16: ='ISIAN DATA'!H21 -> KEC. WATUKUMPUL KAB. PEMALANG
C18: ='ISIAN DATA'!H23 -> TOHIRIN
C19: ='ISIAN DATA'!H24 -> 3327040107730222
C20: ='ISIAN DATA'!H25 -> PEMALANG, 1 JULI 1973
C21: ='ISIAN DATA'!H28 -> WIRASWASTA
C22: ='ISIAN DATA'!H29 -> DK. TAMBI RT 002 RW 001 TAMBI
C23: ='ISIAN DATA'!H30 -> KEC. WATUKUMPUL KAB. PEMALANG
C25: ='ISIAN DATA'!H32 -> KARIPAH
C26: ='ISIAN DATA'!H33 -> 3327044107740064
C27: ='ISIAN DATA'!H34 -> PEMALANG, 1 JULI 1974
C28: ='ISIAN DATA'!H37 -> MENGURUS RUMAH TANGGA
C29: ='ISIAN DATA'!H38 -> DK. TAMBI RT 002 RW 001 TAMBI
C30: ='ISIAN DATA'!H39 -> KEC. WATUKUMPUL KAB. PEMALANG
C31: ==============
C32: ='ISIAN DATA'!H42 -> FIKA INTAN ELMASARI
C33: ='ISIAN DATA'!H43 -> 3327034810050002
C34: ='ISIAN DATA'!H44 -> PEMALANG, 8 OKTOBER 2005
C35: ='ISIAN DATA'!H45 -> PELAJAR MAHASISWA
C36: ='ISIAN DATA'!H47 -> PERAWAN (BELUM KAWIN)
C37: ='ISIAN DATA'!H48 -> DSN SIMADU RT 003 RW 008 DESA BADAK
C38: ='ISIAN DATA'!H49 -> KECAMATAN BELIK KABUPATEN PEMALANG
C40: ='ISIAN DATA'!H51 -> SAMIUN
C41: ='ISIAN DATA'!H52 -> 3327031103810011
C42: ='ISIAN DATA'!H53 -> PEMALANG, 11 MARET 1981
C43: ='ISIAN DATA'!H56 -> PETANI
C44: ='ISIAN DATA'!H57 -> DSN SIMADU RT 003 RW 008 DESA BADAK
C45: ='ISIAN DATA'!H58 -> KECAMATAN BELIK KABUPATEN PEMALANG
C47: ='ISIAN DATA'!H60 -> SRINANI
...

Sheet Kamus
C2: Isi terlebih dahulu data KAMUS ini dan hasilnya tinggal memilih di Tab Pilihan!
D3: << Menu Utama
C4: KAMUS PETUGAS PENGANTAR PENDAFTARAN NIKAH
C5: 01 | D5: Chalim Muchtarom, S.Pd.I
C6: 02
C7: 03
C8: 04
C9: 05
C11: KAMUS LOKASI AKAD NIKAH (Cukup Sampai Desanya Saja)
C12: 01 | D12: DK. Tambi RT 001 RW 001 Tambi | G12: =IF('ISIAN DATA'!$E$11="KANTOR","",Kamus!D12) -> DK. Tambi RT 001 RW 001 Tambi
C13: 02 | D13: DK. Tambi RT 002 RW 001 Tambi | G13: =IF('ISIAN DATA'!$E$11="KANTOR","",D13) -> DK. Tambi RT 002 RW 001 Tambi
C14: 03 | D14: DK. Karanggintung RT 004 RW 001 Tambi | G14: =IF('ISIAN DATA'!$E$11="KANTOR","",Kamus!D14) -> DK. Karanggintung RT 004 RW 001 Tambi
C15: 04 | D15: DK. Sambeng RT 003 RW 001 Tambi | G15: =IF('ISIAN DATA'!$E$11="KANTOR","",Kamus!D15) -> DK. Sambeng RT 003 RW 001 Tambi
C16: 05 | D16: DK. Batur RT 001 RW 002 Tambi | G16: =IF('ISIAN DATA'!$E$11="KANTOR","",Kamus!D16) -> DK. Batur RT 001 RW 002 Tambi
C17: 06 | D17: DK. Jambu Tengah RT 002 RW 002 Tambi | G17: =IF('ISIAN DATA'!$E$11="KANTOR","",Kamus!D17) -> DK. Jambu Tengah RT 002 RW 002 Tambi
C18: 07 | D18: DK. Jambu Lor RT 003 RW 002 Tambi | G18: =IF('ISIAN DATA'!$E$11="KANTOR","",Kamus!D18) -> DK. Jambu Lor RT 003 RW 002 Tambi
C19: 08 | D19: DK. Jambu Tengah RT 004 RW 002 Tambi | G19: =IF('ISIAN DATA'!$E$11="KANTOR","",Kamus!D19) -> DK. Jambu Tengah RT 004 RW 002 Tambi
C20: 09 | D20: DK. Jambu Wetan RT 001 RW 003 Tambi | G20: =IF('ISIAN DATA'!$E$11="KANTOR","",Kamus!D20) -> DK. Jambu Wetan RT 001 RW 003 Tambi
C21: 10 | D21: DK. Jambu Wetan RT 002 RW 003 Tambi | G21: =IF('ISIAN DATA'!$E$11="KANTOR","",Kamus!D21) -> DK. Jambu Wetan RT 002 RW 003 Tambi
C22: 11 | D22: DK. Jambu Kidul RT 003 RW 003 Tambi | G22: =IF('ISIAN DATA'!$E$11="KANTOR","",Kamus!D22) -> DK. Jambu Kidul RT 003 RW 003 Tambi
C23: 12 | D23: DK. Tambah Reja RT 004 RW 003 Tambi | G23: =IF('ISIAN DATA'!$E$11="KANTOR","",Kamus!D23) -> DK. Tambah Reja RT 004 RW 003 Tambi
C24: 13 | D24: DK. Bentang RT 001 RW 004 Tambi | G24: =IF('ISIAN DATA'!$E$11="KANTOR","",Kamus!D24) -> DK. Bentang RT 001 RW 004 Tambi
C25: 14 | D25: DK. Bentang RT 002 RW 004 Tambi | G25: =IF('ISIAN DATA'!$E$11="KANTOR","",Kamus!D25) -> DK. Bentang RT 002 RW 004 Tambi
... C31: 20 | D31: … | G31: =IF('ISIAN DATA'!$E$11="KANTOR","",Kamus!D31) -> …
C33: KAMUS ALASAN DISPENSASI WAKTU AKAD NIKAH
C34: 01 | D34: KEPENTINGAN DINAS/ TUGAS NEGARA | G34: =IF('ISIAN DATA'!$D$9="","",Kamus!D34)
C35: 02 | D35: KETERBATASAN WAKTU CUTI DARI PERUSAHAAN | G35: =IF('ISIAN DATA'!$D$9="","",Kamus!D35)
C36: 03 | D36: KETERBATASAN WAKTU CUTI DARI PEMBERI KERJA | G36: =IF('ISIAN DATA'!$D$9="","",Kamus!D36)
C37: 04 | D37: DARURAT KESEHATAN ORANG TUA | G37: =IF('ISIAN DATA'!$D$9="","",Kamus!D37)
C38: 05 | D38: … | G38: =IF('ISIAN DATA'!$D$9="","",Kamus!D38)
C39: 06 | D39: … | G39: =IF('ISIAN DATA'!$D$9="","",Kamus!D39)
C40: 07 | D40: WALI KRITIS (DARURAT KESEHATAN) | G40: =IF('ISIAN DATA'!$D$9="","",Kamus!D40)
